Workbook

Sheet Version
A1: title | B1: version | C1: author
A2: SNUPia 동아리방 소장자료 일람표 | B2: 2025.06.25 | C2: 김연준, 김승민
A4: Catalog 시트 작성 요령:
A5: 필수 작성 항목
A6: 선택 작성 항목
A7: 자동으로 입력되는 항목

Sheet Catalog
A1: id | B1: title_kor | C1: title_org | D1: composer_org | E1: composer_kor | F1: transcription | G1: era | H1: era_eng | I1: publisher | J1: isbn | K1: description | L1: opus | M1: condition | N1: doner | O1: desc2 | P1: img | Q1: webimg | R1: isInstr
B2: 한글 제목 | C2: 원제 | D2: 작곡가 이름(원어) | E2: 작곡가 이름(한글) | F2: 편곡자, 재편곡자 이름 | G2: 장르 및 시대 | I2: 출판사 | J2: ISBN | K2: 수록 곡 등 설명 | L2: 수록 곡의 작품번호 | M2: 보존 상태(3~1) | N2: 기증자 정보 | O2: 비고 | P2: 이미지 path | Q2: 이미지(웹) url | R2: 교본인지 여부
A3: 1 | B3: Händel Klavier-Werke | D3: George Frideric Handel | E3: =_xlfn.XLOOKUP(D3, Composer!A:A, Composer!B:B, "-") -> 게오르크 프리드리히 헨델 | G3: =_xlfn.XLOOKUP(D3, Composer!A:A, Composer!C:C, "-") -> 바로크 | H3: =_xlfn.XLOOKUP(E3, Composer!B:B, Composer!D:D, "-") -> Baroque | I3: 세광음악출판사 | K3: Suiten (Selections), 3 Leçons, Chaconne con Variazioni, Fantasia, Fuga I | L3: Suites -> HWV 426, 428, 429, 430, 431, 432, 439, 436, 437, 441, 452 Leçons -> 434, 435 Chaconne con Variazioni -> 442 Fantasia -> 490, Fuga -> 605 | M3: 3 | P3: handel1.jpg
A4: 2 | B4: D.Scarlatti Piano-Opere 1 | D4: Domenico Scarlatti | E4: =_xlfn.XLOOKUP(D4, Composer!A:A, Composer!B:B, "-") -> 도메니코 스카를라티 | G4: =_xlfn.XLOOKUP(D4, Composer!A:A, Composer!C:C, "-") -> 바로크 | H4: =_xlfn.XLOOKUP(E4, Composer!B:B, Composer!D:D, "-") -> Baroque | I4: 태림출판사 | K4: 50 Sonate | L4: S.L.2 / S.L.3 / S.L.15 / L.2 / L.3 / L.5 / L.6 / L.10 / L.14 / L.17 / L.20 / L.21 / L.22 (K.198) / L.23 (K.380) / L.25 / L.31 / L.32 / L.33(K.87) / L.34 / L.35 / L.43 / L.48 / L.50 / L.54 / L.58 / L.84 / L.90 / L.93 / L.97 / L.98 / L.103 / L.104 / L.107 / L.108 (K.213) / L.109 / L.111 / L.119 / L.122 / L.127 / L.129 / L.132 / L.139 / L.141 / L.142 / L.148 / L.152 / L.164 / L.171 / L.172 / L.182 | M4: 3 | O4: 소나타 13번에 표시 되어있음
A5: 3 | B5: D.Scarlatti Piano-Opere 2 | D5: Domenico Scarlatti | E5: =_xlfn.XLOOKUP(D5, Composer!A:A, Composer!B:B, "-") -> 도메니코 스카를라티 | G5: =_xlfn.XLOOKUP(D5, Composer!A:A, Composer!C:C, "-") -> 바로크 | H5: =_xlfn.XLOOKUP(E5, Composer!B:B, Composer!D:D, "-") -> Baroque | I5: 태림출판사 | K5: 50 Sonate | L5: L.186 / L.187 / L.188 / L.193 / L.195 / L.203 / L.205 / L.208 / L.209 (K.455) / L.210 / L.215 / L.224 / L.225 / L.231 / L.232 / L.234 / L.241 / L.243 / L.245 / L.249 / L.256 / L.257 / L.258 / L.259 / L.260 / L.263 / L.267 / L.282 / L.286 / L.288 / L.290 / L.293 / L.294 / L.300 / L.301 / L.307 / L.318 / L.324 / L.325 / L.327 / L.331 / L.335 / L.338 / L.340 (K.476) / L.343 / L.344 / L.345 / L.347 / L.348 / L.349 | M5: 3
A6: 4 | B6: J.S.Bach Klavier-Werke 2 | D6: Johann Sebastian Bach | E6: =_xlfn.XLOOKUP(D6, Composer!A:A, Composer!B:B, "-") -> 요한 세바스티안 바흐 | G6: =_xlfn.XLOOKUP(D6, Composer!A:A, Composer!C:C, "-") -> 바로크 | H6: =_xlfn.XLOOKUP(E6, Composer!B:B, Composer!D:D, "-") -> Baroque | I6: 세광음악출판사 | K6: Wohltemperiertes Klavier, 48 Präludein und Fugen | L6: BWV 846–893 | M6: 3 | P6: bach1.jpg
A7: 5 | B7: J.S.Bach Klavier-Werke 3 | D7: Johann Sebastian Bach | E7: =_xlfn.XLOOKUP(D7, Composer!A:A, Composer!B:B, "-") -> 요한 세바스티안 바흐 | G7: =_xlfn.XLOOKUP(D7, Composer!A:A, Composer!C:C, "-") -> 바로크 | H7: =_xlfn.XLOOKUP(E7, Composer!B:B, Composer!D:D, "-") -> Baroque | I7: 세광음악출판사 | K7: Französische Suiten, Englische Suiten | L7: BWV 806-811, 812-817 | M7: 3 | P7: bach2.jpg
A8: 6 | B8: Johann Sebastian Bach Partiten Goldberg-Variationen | D8: Johann Sebastian Bach | E8: =_xlfn.XLOOKUP(D8, Composer!A:A, Composer!B:B, "-") -> 요한 세바스티안 바흐 | G8: =_xlfn.XLOOKUP(D8, Composer!A:A, Composer!C:C, "-") -> 바로크 | H8: =_xlfn.XLOOKUP(E8, Composer!B:B, Composer!D:D, "-") -> Baroque | I8: 동화출판사 | K8: Partiten, Goldberg-Variationen | L8: BWV 825-830, 988 | M8: 3 | P8: bach3.jpg
A9: 7 | B9: Johann Sebastian Bach Das Wohltemperierte Klavier I·II | D9: Johann Sebastian Bach | E9: =_xlfn.XLOOKUP(D9, Composer!A:A, Composer!B:B, "-") -> 요한 세바스티안 바흐 | G9: =_xlfn.XLOOKUP(D9, Composer!A:A, Composer!C:C, "-") -> 바로크 | H9: =_xlfn.XLOOKUP(E9, Composer!B:B, Composer!D:D, "-") -> Baroque | I9: 동화출판사 | K9: Das Wohltemperierte Klavier I, Das Wohltemperierte Klavier II | L9: BWV 846-869, 870~893 | M9: 3 | P9: bach4.jpg
A10: 8 | B10: J.S.Bach Das Wohletemperierte Klavier Teil I | D10: Johann Sebastian Bach | E10: =_xlfn.XLOOKUP(D10, Composer!A:A, Composer!B:B, "-") -> 요한 세바스티안 바흐 | G10: =_xlfn.XLOOKUP(D10, Composer!A:A, Composer!C:C, "-") -> 바로크 | H10: =_xlfn.XLOOKUP(E10, Composer!B:B, Composer!D:D, "-") -> Baroque | I10: G. Henle Verlag | K10: Das Wohltemperierte Klavier I | L10: BWV 846-869 | M10: 2 | N10: 문상혁 | O10: 표지 찢겨져 있음 | Q10: https://contents.kyobobook.co.kr/sih/fit-in/458x0/pdt/9790201810140.jpg
A11: 9 | B11: J.S.Bach Klavier-Werke 4 | D11: Johann Sebastian Bach | E11: =_xlfn.XLOOKUP(D11, Composer!A:A, Composer!B:B, "-") -> 요한 세바스티안 바흐 | G11: =_xlfn.XLOOKUP(D11, Composer!A:A, Composer!C:C, "-") -> 바로크 | H11: =_xlfn.XLOOKUP(E11, Composer!B:B, Composer!D:D, "-") -> Baroque | I11: 태림출판사 | K11: 15 Inventionen, 15 Symphonien, Kleine Präludien, Fughetten | L11: BWV 772-786, 787-801 | M11: 3
A12: 10 | B12: J.S.Bach Klavier-Werke 5 | D12: Johann Sebastian Bach | E12: =_xlfn.XLOOKUP(D12, Composer!A:A, Composer!B:B, "-") -> 요한 세바스티안 바흐 | G12: =_xlfn.XLOOKUP(D12, Composer!A:A, Composer!C:C, "-") -> 바로크 | H12: =_xlfn.XLOOKUP(E12, Composer!B:B, Composer!D:D, "-") -> Baroque | I12: 현대악보출판사 | K12: Partiten, Französische Ouvertüre, Italienisches Konzert, Chromatische Phantasie Und Fuge, Capriccio | L12: BWV 924–930, 939–942, 999, 933-938, 961, 952, 953, 899, | M12: 3 | P12: bach5.jpg
A13: 11 | B13: J.S.Bach Klavier-Werke 6 | D13: Johann Sebastian Bach | E13: =_xlfn.XLOOKUP(D13, Composer!A:A, Composer!B:B, "-") -> 요한 세바스티안 바흐 | G13: =_xlfn.XLOOKUP(D13, Composer!A:A, Composer!C:C, "-") -> 바로크 | H13: =_xlfn.XLOOKUP(E13, Composer!B:B, Composer!D:D, "-") -> Baroque | I13: 현대악보출판사 | K13: Toccaten | M13: 3 | P13: bach6.jpg
A14: 12 | B14: Mozart Klavier-Werke 1 | D14: Wolfgang Amadeus Mozart | E14: =_xlfn.XLOOKUP(D14, Composer!A:A, Composer!B:B, "-") -> 볼프강 아마데우스 모차르트 | G14: =_xlfn.XLOOKUP(D14, Composer!A:A, Composer!C:C, "-") -> 고전 | H14: =_xlfn.XLOOKUP(E14, Composer!B:B, Composer!D:D, "-") -> Classical | I14: 태림출판사 | K14: Sonate Nr.1-10 | M14: 2
A15: 13 | B15: 모차르트 소나타전집2 | C15: Mozart Klaviersonaten 2 | D15: Wolfgang Amadeus Mozart | E15: =_xlfn.XLOOKUP(D15, Composer!A:A, Composer!B:B, "-") -> 볼프강 아마데우스 모차르트 | G15: =_xlfn.XLOOKUP(D15, Composer!A:A, Composer!C:C, "-") -> 고전 | H15: =_xlfn.XLOOKUP(E15, Composer!B:B, Composer!D:D, "-") -> Classical | I15: 음악춘추사 | K15: Sonate Nr.11-19, Fantasie Nr.4 | M15: 3 | P15: mozart1.jpg
A16: 14 | B16: Haydn Klavier-Werke | D16: Franz Joseph Haydn | E16: =_xlfn.XLOOKUP(D16, Composer!A:A, Composer!B:B, "-") -> 프란츠 요제프 하이든 | G16: =_xlfn.XLOOKUP(D16, Composer!A:A, Composer!C:C, "-") -> 고전 | H16: =_xlfn.XLOOKUP(E16, Composer!B:B, Composer!D:D, "-") -> Classical | I16: 음악춘추사 | K16: Sonatas, Vol.1 | M16: 2 | P16: haydn4.jpg
A17: 15 | B17: Haydn Klavier-Werke | D17: Franz Joseph Haydn | E17: =_xlfn.XLOOKUP(D17, Composer!A:A, Composer!B:B, "-") -> 프란츠 요제프 하이든 | G17: =_xlfn.XLOOKUP(D17, Composer!A:A, Composer!C:C, "-") -> 고전 | H17: =_xlfn.XLOOKUP(E17, Composer!B:B, Composer!D:D, "-") -> Classical | I17: 음악춘추사 | K17: Sonatas, Vol.2 | M17: 2 | P17: haydn3.jpg
A18: 16 | B18: Haydn Klavier-Werke | D18: Franz Joseph Haydn | E18: =_xlfn.XLOOKUP(D18, Composer!A:A, Composer!B:B, "-") -> 프란츠 요제프 하이든 | G18: =_xlfn.XLOOKUP(D18, Composer!A:A, Composer!C:C, "-") -> 고전 | H18: =_xlfn.XLOOKUP(E18, Composer!B:B, Composer!D:D, "-") -> Classical | I18: 음악춘추사 | K18: Sonatas, Vol.3 | M18: 2 | P18: haydn2.jpg
A19: 17 | B19: Haydn Klavier-Werke | D19: Franz Joseph Haydn | E19: =_xlfn.XLOOKUP(D19, Composer!A:A, Composer!B:B, "-") -> 프란츠 요제프 하이든 | G19: =_xlfn.XLOOKUP(D19, Composer!A:A, Composer!C:C, "-") -> 고전 | H19: =_xlfn.XLOOKUP(E19, Composer!B:B, Composer!D:D, "-") -> Classical | I19: 세광음악출판사 | K19: Sonaten, Tema con Variazioni, Andante con Variazioni, Fantasia, Capriccio | M19: 3 | P19: haydn1.jpg
A20: 18 | B20: Haydn Complete Piano Sonatas | C20: Haydn Sämtliche Klaviersonaten Band III | D20: Franz Joseph Haydn | E20: =_xlfn.XLOOKUP(D20, Composer!A:A, Composer!B:B, "-") -> 프란츠 요제프 하이든 | G20: =_xlfn.XLOOKUP(D20, Composer!A:A, Composer!C:C, "-") -> 고전 | H20: =_xlfn.XLOOKUP(E20, Composer!B:B, Composer!D:D, "-") -> Classical | I20: G. Henle Verlag | K20: Volume III | M20: 2 | N20: 문상혁 | Q20: https://m.media-amazon.com/images/I/5101QsDC8PL._AC_UF1000,1000_QL80_.jpg
A21: 19 | B21: Haydn Piano Variations | C21: Haydn Variationen für Klavier | D21: Franz Joseph Haydn | E21: =_xlfn.XLOOKUP(D21, Composer!A:A, Composer!B:B, "-") -> 프란츠 요제프 하이든 | G21: =_xlfn.XLOOKUP(D21, Composer!A:A, Composer!C:C, "-") -> 고전 | H21: =_xlfn.XLOOKUP(E21, Composer!B:B, Composer!D:D, "-") -> Classical | I21: G. Henle Verlag | K21: Piano Variations | M21: 2 | N21: 문상혁
A22: 20 | B22: Haydn 2 | D22: Franz Joseph Haydn | E22: =_xlfn.XLOOKUP(D22, Composer!A:A, Composer!B:B, "-") -> 프란츠 요제프 하이든 | G22: =_xlfn.XLOOKUP(D22, Composer!A:A, Composer!C:C, "-") -> 고전 | H22: =_xlfn.XLOOKUP(E22, Composer!B:B, Composer!D:D, "-") -> Classical | I22: 세광음악출판사 | K22: Sonaten 2 | M22: 3 | P22: haydn5.jpg
A23: 21 | B23: Mozart Piano Sonantas | C23: Mozart Klaviersonaten Band 2 | D23: Wolfgang Amadeus Mozart | E23: =_xlfn.XLOOKUP(D23, Composer!A:A, Composer!B:B, "-") -> 볼프강 아마데우스 모차르트 | G23: =_xlfn.XLOOKUP(D23, Composer!A:A, Composer!C:C, "-") -> 고전 | H23: =_xlfn.XLOOKUP(E23, Composer!B:B, Composer!D:D, "-") -> Classical | I23: G. Henle Verlag | K23: (스프링 제본) Volume II | M23: 3 | N23: 문상혁
A24: 22 | B24: Beethoven Variationene für Klavier | D24: Ludwig van Beethoven | E24: =_xlfn.XLOOKUP(D24, Composer!A:A, Composer!B:B, "-") -> 루트비히 판 베토벤 | G24: =_xlfn.XLOOKUP(D24, Composer!A:A, Composer!C:C, "-") -> 고전 | H24: =_xlfn.XLOOKUP(E24, Composer!B:B, Composer!D:D, "-") -> Classical | I24: G. Henle Verlag | K24: Band II | M24: 2 | N24: 문상혁
A25: 23 | B25: Beethoven Piano Concerto no. 4 in G major | C25: Klavierkonzert Nr.4 G-dur Opus 58 Klavierauszug | D25: Ludwig van Beethoven | E25: =_xlfn.XLOOKUP(D25, Composer!A:A, Composer!B:B, "-") -> 루트비히 판 베토벤 | G25: =_xlfn.XLOOKUP(D25, Composer!A:A, Composer!C:C, "-") -> 고전 | H25: =_xlfn.XLOOKUP(E25, Composer!B:B, Composer!D:D, "-") -> Classical | I25: G. Henle Verlag | K25: op.58, Piano Reduction | M25: 3 | N25: 문상혁
A26: 24 | B26: Beethoven Klavier-Werke 4 | D26: Ludwig van Beethoven | E26: =_xlfn.XLOOKUP(D26, Composer!A:A, Composer!B:B, "-") -> 루트비히 판 베토벤 | G26: =_xlfn.XLOOKUP(D26, Composer!A:A, Composer!C:C, "-") -> 고전 | H26: =_xlfn.XLOOKUP(E26, Composer!B:B, Composer!D:D, "-") -> Classical | I26: 현대음악출판사 | K26: Variationen | M26: 3
A27: 25 | B27: Beethoven Klavier-Werke 5 | D27: Ludwig van Beethoven | E27: =_xlfn.XLOOKUP(D27, Composer!A:A, Composer!B:B, "-") -> 루트비히 판 베토벤 | G27: =_xlfn.XLOOKUP(D27, Composer!A:A, Composer!C:C, "-") -> 고전 | H27: =_xlfn.XLOOKUP(E27, Composer!B:B, Composer!D:D, "-") -> Classical | I27: 태림출판사 | K27: Sieben Bagetelen Op.33 외 | M27: 3
A28: 26 | B28: 베토벤 소나타전집 1 | C28: Beethoven Klaviersonaten 1 | D28: Ludwig van Beethoven | E28: =_xlfn.XLOOKUP(D28, Composer!A:A, Composer!B:B, "-") -> 루트비히 판 베토벤 | G28: =_xlfn.XLOOKUP(D28, Composer!A:A, Composer!C:C, "-") -> 고전 | H28: =_xlfn.XLOOKUP(E28, Composer!B:B, Composer!D:D, "-") -> Classical | I28: 음악춘추사 | K28: Band 1. Sonaten Nr. 1-4 | M28: 3 | P28: beethoven2.jpg
A29: 27 | B29: 베토벤 소나타전집 2 | C29: Beethoven Klaviersonaten 2 | D29: Ludwig van Beethoven | E29: =_xlfn.XLOOKUP(D29, Composer!A:A, Composer!B:B, "-") -> 루트비히 판 베토벤 | G29: =_xlfn.XLOOKUP(D29, Composer!A:A, Composer!C:C, "-") -> 고전 | H29: =_xlfn.XLOOKUP(E29, Composer!B:B, Composer!D:D, "-") -> Classical | I29: 음악춘추사 | K29: Band 2. Sonaten Nr. 5-10 | M29: 3 | P29: beethoven3.jpg
A30: 28 | B30: 베토벤 소나타전집 3 | C30: Beethoven Klaviersonaten 3 | D30: Ludwig van Beethoven | E30: =_xlfn.XLOOKUP(D30, Composer!A:A, Composer!B:B, "-") -> 루트비히 판 베토벤 | G30: =_xlfn.XLOOKUP(D30, Composer!A:A, Composer!C:C, "-") -> 고전 | H30: =_xlfn.XLOOKUP(E30, Composer!B:B, Composer!D:D, "-") -> Classical | I30: 음악춘추사 | K30: Band 3. Sonaten Nr. 11-15 | M30: 3 | P30: beethoven4.jpg
A31: 29 | B31: 베토벤 소나타전집 4 | C31: Beethoven Klaviersonaten 4 | D31: Ludwig van Beethoven | E31: =_xlfn.XLOOKUP(D31, Composer!A:A, Composer!B:B, "-") -> 루트비히 판 베토벤 | G31: =_xlfn.XLOOKUP(D31, Composer!A:A, Composer!C:C, "-") -> 고전 | H31: =_xlfn.XLOOKUP(E31, Composer!B:B, Composer!D:D, "-") -> Classical | I31: 음악춘추사 | K31: Band 4. Sonaten Nr. 16-20 | M31: 3 | P31: beethoven5.jpg
A32: 30 | B32: 베토벤 소나타전집 5 | C32: Beethoven Klaviersonaten 5 | D32: Ludwig van Beethoven | E32: =_xlfn.XLOOKUP(D32, Composer!A:A, Composer!B:B, "-") -> 루트비히 판 베토벤 | G32: =_xlfn.XLOOKUP(D32, Composer!A:A, Composer!C:C, "-") -> 고전 | H32: =_xlfn.XLOOKUP(E32, Composer!B:B, Composer!D:D, "-") -> Classical | I32: 음악춘추사 | K32: Band 5. Sonaten Nr. 21-27 | M32: 3 | P32: beethoven6.jpg
A33: 31 | B33: 베토벤 소나타전집 6 | C33: Beethoven Klaviersonaten 6 | D33: Ludwig van Beethoven | E33: =_xlfn.XLOOKUP(D33, Composer!A:A, Composer!B:B, "-") -> 루트비히 판 베토벤 | G33: =_xlfn.XLOOKUP(D33, Composer!A:A, Composer!C:C, "-") -> 고전 | H33: =_xlfn.XLOOKUP(E33, Composer!B:B, Composer!D:D, "-") -> Classical | I33: 음악춘추사 | K33: Band 6. Sonaten Nr. 28-32 | M33: 3 | P33: beethoven7.jpg
A34: 32 | B34: 클레멘티 소나타집 2 | C34: Clementi Sonaten 2 | D34: Muzio Clementi | E34: =_xlfn.XLOOKUP(D34, Composer!A:A, Composer!B:B, "-") -> 무치오 클레멘티 | G34: =_xlfn.XLOOKUP(D34, Composer!A:A, Composer!C:C, "-") -> 고전 | H34: =_xlfn.XLOOKUP(E34, Composer!B:B, Composer!D:D, "-") -> Classical | I34: 음악춘추사 | K34: Band 4. Sonate 19-24 | M34: 1 | P34: clementi1.jpg
A35: 33 | B35: 클레멘티 소나타집 4 | C35: Clementi Sonaten 4 | D35: Muzio Clementi | E35: =_xlfn.XLOOKUP(D35, Composer!A:A, Composer!B:B, "-") -> 무치오 클레멘티 | G35: =_xlfn.XLOOKUP(D35, Composer!A:A, Composer!C:C, "-") -> 고전 | H35: =_xlfn.XLOOKUP(E35, Composer!B:B, Composer!D:D, "-") -> Classical | I35: 음악춘추사 | K35: Band 4. Sonate 8-12 | M35: 2
A36: 34 | B36: 베토벤 작품집 2 | C36: Beethoven Klavierstücke 2 | D36: Ludwig van Beethoven | E36: =_xlfn.XLOOKUP(D36, Composer!A:A, Composer!B:B, "-") -> 루트비히 판 베토벤 | G36: =_xlfn.XLOOKUP(D36, Composer!A:A, Composer!C:C, "-") -> 고전 | H36: =_xlfn.XLOOKUP(E36, Composer!B:B, Composer!D:D, "-") -> Classical | I36: 음악춘추사 | K36: Werke der Bonner Zeit, Zerke der Früheren Wiener Zeit, Werke der Späteren Wiener Jahre | M36: 3 | P36: beethoven1.jpg
A37: 35 | B37: Beethoven Sonata 1 | D37: Ludwig van Beethoven | E37: =_xlfn.XLOOKUP(D37, Composer!A:A, Composer!B:B, "-") -> 루트비히 판 베토벤 | G37: =_xlfn.XLOOKUP(D37, Composer!A:A, Composer!C:C, "-") -> 고전 | H37: =_xlfn.XLOOKUP(E37, Composer!B:B, Composer!D:D, "-") -> Classical | I37: 정보 없음 | K37: (스프링 제본) | M37: 3
A38: 36 | B38: Schubert Klavier-Werke 1 | D38: Franz Peter Schubert | E38: =_xlfn.XLOOKUP(D38, Composer!A:A, Composer!B:B, "-") -> 프란츠 페터 슈베르트 | G38: =_xlfn.XLOOKUP(D38, Composer!A:A, Composer!C:C, "-") -> 낭만 | H38: =_xlfn.XLOOKUP(E38, Composer!B:B, Composer!D:D, "-") -> Romantic | I38: 현대음악출판사 | K38: Sonaten 1 | L38: 1. Op.42 a-moll / 2. Op.53 D-dur / 3. Op.120 A-dur / 4. Op.122 Es-dur / 5. Op.143 a-moll, 6. Op.147 H-dur | M38: 3 | P38: schubert5.jpg
A39: 37 | B39: 슈베르트 소나타집 1 | C39: Schubert Klaviersonaten 1 | D39: Franz Peter Schubert | E39: =_xlfn.XLOOKUP(D39, Composer!A:A, Composer!B:B, "-") -> 프란츠 페터 슈베르트 | G39: =_xlfn.XLOOKUP(D39, Composer!A:A, Composer!C:C, "-") -> 낭만 | H39: =_xlfn.XLOOKUP(E39, Composer!B:B, Composer!D:D, "-") -> Romantic | I39: 음악춘추사 | K39: Band 1. Sonaten Nr. 1-4 | L39: D.537 / D.568 / D.575 / D.664 | M39: 3 | P39: schubert1.jpg
A40: 38 | B40: 슈베르트 소나타집 2 | C40: Schubert Klaviersonaten 2 | D40: Franz Peter Schubert | E40: =_xlfn.XLOOKUP(D40, Composer!A:A, Composer!B:B, "-") -> 프란츠 페터 슈베르트 | G40: =_xlfn.XLOOKUP(D40, Composer!A:A, Composer!C:C, "-") -> 낭만 | H40: =_xlfn.XLOOKUP(E40, Composer!B:B, Composer!D:D, "-") -> Romantic | I40: 음악춘추사 | K40: Band 2. Sonaten Nr. 4-7 | L40: D.664 / D.784 / D.845 / D.850 | M40: 3 | P40: schubert2.jpg
...

Sheet Catalog의 사본
A1: id | B1: title_kor | C1: title_org | D1: composer_org | E1: composer_kor | F1: transcription | G1: era | H1: era_eng | I1: publisher | J1: isbn | K1: description | L1: opus | M1: condition | N1: doner | O1: desc2 | P1: img | Q1: webimg | R1: isInstr
B2: 한글 제목 | C2: 원제 | D2: 작곡가 이름(원어) | E2: 작곡가 이름(한글) | F2: 편곡자, 재편곡자 이름 | G2: 장르 및 시대 | I2: 출판사 | J2: ISBN | K2: 수록 곡 등 설명 | L2: 수록 곡의 작품번호 | M2: 보존 상태(3~1) | N2: 기증자 정보 | O2: 비고 | P2: 이미지 path | Q2: 이미지(웹) url | R2: 교본인지 여부
A3: 1 | B3: Händel Klavier-Werke | D3: George Frideric Handel | E3: =_xlfn.XLOOKUP(D3, Composer!A:A, Composer!B:B, "-") -> 게오르크 프리드리히 헨델 | G3: =_xlfn.XLOOKUP(D3, Composer!A:A, Composer!C:C, "-") -> 바로크 | H3: =_xlfn.XLOOKUP(E3, Composer!B:B, Composer!D:D, "-") -> Baroque | I3: 세광음악출판사 | K3: Suiten (Selections), 3 Leçons, Chaconne con Variazioni, Fantasia, Fuga I | L3: Suites -> HWV 426, 428, 429, 430, 431, 432, 439, 436, 437, 441, 452 Leçons -> 434, 435 Chaconne con Variazioni -> 442 Fantasia -> 490, Fuga -> 605 | M3: 3 | P3: handel1.jpg
A4: 2 | B4: D.Scarlatti Piano-Opere 1 | D4: Domenico Scarlatti | E4: =_xlfn.XLOOKUP(D4, Composer!A:A, Composer!B:B, "-") -> 도메니코 스카를라티 | G4: =_xlfn.XLOOKUP(D4, Composer!A:A, Composer!C:C, "-") -> 바로크 | H4: =_xlfn.XLOOKUP(E4, Composer!B:B, Composer!D:D, "-") -> Baroque | I4: 태림출판사 | K4: 50 Sonate | L4: S.L.2 / S.L.3 / S.L.15 / L.2 / L.3 / L.5 / L.6 / L.10 / L.14 / L.17 / L.20 / L.21 / L.22 (K.198) / L.23 (K.380) / L.25 / L.31 / L.32 / L.33(K.87) / L.34 / L.35 / L.43 / L.48 / L.50 / L.54 / L.58 / L.84 / L.90 / L.93 / L.97 / L.98 / L.103 / L.104 / L.107 / L.108 (K.213) / L.109 / L.111 / L.119 / L.122 / L.127 / L.129 / L.132 / L.139 / L.141 / L.142 / L.148 / L.152 / L.164 / L.171 / L.172 / L.182 | M4: 3 | O4: 소나타 13번에 표시 되어있음
A5: 3 | B5: D.Scarlatti Piano-Opere 2 | D5: Domenico Scarlatti | E5: =_xlfn.XLOOKUP(D5, Composer!A:A, Composer!B:B, "-") -> 도메니코 스카를라티 | G5: =_xlfn.XLOOKUP(D5, Composer!A:A, Composer!C:C, "-") -> 바로크 | H5: =_xlfn.XLOOKUP(E5, Composer!B:B, Composer!D:D, "-") -> Baroque | I5: 태림출판사 | K5: 50 Sonate | L5: L.186 / L.187 / L.188 / L.193 / L.195 / L.203 / L.205 / L.208 / L.209 (K.455) / L.210 / L.215 / L.224 / L.225 / L.231 / L.232 / L.234 / L.241 / L.243 / L.245 / L.249 / L.256 / L.257 / L.258 / L.259 / L.260 / L.263 / L.267 / L.282 / L.286 / L.288 / L.290 / L.293 / L.294 / L.300 / L.301 / L.307 / L.318 / L.324 / L.325 / L.327 / L.331 / L.335 / L.338 / L.340 (K.476) / L.343 / L.344 / L.345 / L.347 / L.348 / L.349 | M5: 3
A6: 4 | B6: J.S.Bach Klavier-Werke 2 | D6: Johann Sebastian Bach | E6: =_xlfn.XLOOKUP(D6, Composer!A:A, Composer!B:B, "-") -> 요한 세바스티안 바흐 | G6: =_xlfn.XLOOKUP(D6, Composer!A:A, Composer!C:C, "-") -> 바로크 | H6: =_xlfn.XLOOKUP(E6, Composer!B:B, Composer!D:D, "-") -> Baroque | I6: 세광음악출판사 | K6: Wohltemperiertes Klavier, 48 Präludein und Fugen | L6: BWV 846–893 | M6: 3 | P6: bach1.jpg
A7: 5 | B7: J.S.Bach Klavier-Werke 3 | D7: Johann Sebastian Bach | E7: =_xlfn.XLOOKUP(D7, Composer!A:A, Composer!B:B, "-") -> 요한 세바스티안 바흐 | G7: =_xlfn.XLOOKUP(D7, Composer!A:A, Composer!C:C, "-") -> 바로크 | H7: =_xlfn.XLOOKUP(E7, Composer!B:B, Composer!D:D, "-") -> Baroque | I7: 세광음악출판사 | K7: Französische Suiten, Englische Suiten | L7: BWV 806-811, 812-817 | M7: 3 | P7: bach2.jpg
A8: 6 | B8: Johann Sebastian Bach Partiten Goldberg-Variationen | D8: Johann Sebastian Bach | E8: =_xlfn.XLOOKUP(D8, Composer!A:A, Composer!B:B, "-") -> 요한 세바스티안 바흐 | G8: =_xlfn.XLOOKUP(D8, Composer!A:A, Composer!C:C, "-") -> 바로크 | H8: =_xlfn.XLOOKUP(E8, Composer!B:B, Composer!D:D, "-") -> Baroque | I8: 동화출판사 | K8: Partiten, Goldberg-Variationen | L8: BWV 825-830, 988 | M8: 3 | P8: bach3.jpg
A9: 7 | B9: Johann Sebastian Bach Das Wohltemperierte Klavier I·II | D9: Johann Sebastian Bach | E9: =_xlfn.XLOOKUP(D9, Composer!A:A, Composer!B:B, "-") -> 요한 세바스티안 바흐 | G9: =_xlfn.XLOOKUP(D9, Composer!A:A, Composer!C:C, "-") -> 바로크 | H9: =_xlfn.XLOOKUP(E9, Composer!B:B, Composer!D:D, "-") -> Baroque | I9: 동화출판사 | K9: Das Wohltemperierte Klavier I, Das Wohltemperierte Klavier II | L9: BWV 846-869, 870~893 | M9: 3 | P9: bach4.jpg
A10: 8 | B10: J.S.Bach Das Wohletemperierte Klavier Teil I | D10: Johann Sebastian Bach | E10: =_xlfn.XLOOKUP(D10, Composer!A:A, Composer!B:B, "-") -> 요한 세바스티안 바흐 | G10: =_xlfn.XLOOKUP(D10, Composer!A:A, Composer!C:C, "-") -> 바로크 | H10: =_xlfn.XLOOKUP(E10, Composer!B:B, Composer!D:D, "-") -> Baroque | I10: G. Henle Verlag | K10: Das Wohltemperierte Klavier I | L10: BWV 846-869 | M10: 2 | N10: 문상혁 | O10: 표지 찢겨져 있음 | Q10: https://contents.kyobobook.co.kr/sih/fit-in/458x0/pdt/9790201810140.jpg
A11: 9 | B11: J.S.Bach Klavier-Werke 4 | D11: Johann Sebastian Bach | E11: =_xlfn.XLOOKUP(D11, Composer!A:A, Composer!B:B, "-") -> 요한 세바스티안 바흐 | G11: =_xlfn.XLOOKUP(D11, Composer!A:A, Composer!C:C, "-") -> 바로크 | H11: =_xlfn.XLOOKUP(E11, Composer!B:B, Composer!D:D, "-") -> Baroque | I11: 태림출판사 | K11: 15 Inventionen, 15 Symphonien, Kleine Präludien, Fughetten | L11: BWV 772-786, 787-801 | M11: 3
A12: 10 | B12: J.S.Bach Klavier-Werke 5 | D12: Johann Sebastian Bach | E12: =_xlfn.XLOOKUP(D12, Composer!A:A, Composer!B:B, "-") -> 요한 세바스티안 바흐 | G12: =_xlfn.XLOOKUP(D12, Composer!A:A, Composer!C:C, "-") -> 바로크 | H12: =_xlfn.XLOOKUP(E12, Composer!B:B, Composer!D:D, "-") -> Baroque | I12: 현대악보출판사 | K12: Partiten, Französische Ouvertüre, Italienisches Konzert, Chromatische Phantasie Und Fuge, Capriccio | L12: BWV 924–930, 939–942, 999, 933-938, 961, 952, 953, 899, | M12: 3 | P12: bach5.jpg
A13: 11 | B13: J.S.Bach Klavier-Werke 6 | D13: Johann Sebastian Bach | E13: =_xlfn.XLOOKUP(D13, Composer!A:A, Composer!B:B, "-") -> 요한 세바스티안 바흐 | G13: =_xlfn.XLOOKUP(D13, Composer!A:A, Composer!C:C, "-") -> 바로크 | H13: =_xlfn.XLOOKUP(E13, Composer!B:B, Composer!D:D, "-") -> Baroque | I13: 현대악보출판사 | K13: Toccaten | M13: 3 | P13: bach6.jpg
A14: 12 | B14: Mozart Klavier-Werke 1 | D14: Wolfgang Amadeus Mozart | E14: =_xlfn.XLOOKUP(D14, Composer!A:A, Composer!B:B, "-") -> 볼프강 아마데우스 모차르트 | G14: =_xlfn.XLOOKUP(D14, Composer!A:A, Composer!C:C, "-") -> 고전 | H14: =_xlfn.XLOOKUP(E14, Composer!B:B, Composer!D:D, "-") -> Classical | I14: 태림출판사 | K14: Sonate Nr.1-10 | M14: 2
A15: 13 | B15: 모차르트 소나타전집2 | C15: Mozart Klaviersonaten 2 | D15: Wolfgang Amadeus Mozart | E15: =_xlfn.XLOOKUP(D15, Composer!A:A, Composer!B:B, "-") -> 볼프강 아마데우스 모차르트 | G15: =_xlfn.XLOOKUP(D15, Composer!A:A, Composer!C:C, "-") -> 고전 | H15: =_xlfn.XLOOKUP(E15, Composer!B:B, Composer!D:D, "-") -> Classical | I15: 음악춘추사 | K15: Sonate Nr.11-19, Fantasie Nr.4 | M15: 3 | P15: mozart1.jpg
A16: 14 | B16: Haydn Klavier-Werke | D16: Franz Joseph Haydn | E16: =_xlfn.XLOOKUP(D16, Composer!A:A, Composer!B:B, "-") -> 프란츠 요제프 하이든 | G16: =_xlfn.XLOOKUP(D16, Composer!A:A, Composer!C:C, "-") -> 고전 | H16: =_xlfn.XLOOKUP(E16, Composer!B:B, Composer!D:D, "-") -> Classical | I16: 음악춘추사 | K16: Sonatas, Vol.1 | M16: 2 | P16: haydn4.jpg
A17: 15 | B17: Haydn Klavier-Werke | D17: Franz Joseph Haydn | E17: =_xlfn.XLOOKUP(D17, Composer!A:A, Composer!B:B, "-") -> 프란츠 요제프 하이든 | G17: =_xlfn.XLOOKUP(D17, Composer!A:A, Composer!C:C, "-") -> 고전 | H17: =_xlfn.XLOOKUP(E17, Composer!B:B, Composer!D:D, "-") -> Classical | I17: 음악춘추사 | K17: Sonatas, Vol.2 | M17: 2 | P17: haydn3.jpg
A18: 16 | B18: Haydn Klavier-Werke | D18: Franz Joseph Haydn | E18: =_xlfn.XLOOKUP(D18, Composer!A:A, Composer!B:B, "-") -> 프란츠 요제프 하이든 | G18: =_xlfn.XLOOKUP(D18, Composer!A:A, Composer!C:C, "-") -> 고전 | H18: =_xlfn.XLOOKUP(E18, Composer!B:B, Composer!D:D, "-") -> Classical | I18: 음악춘추사 | K18: Sonatas, Vol.3 | M18: 2 | P18: haydn2.jpg
A19: 17 | B19: Haydn Klavier-Werke | D19: Franz Joseph Haydn | E19: =_xlfn.XLOOKUP(D19, Composer!A:A, Composer!B:B, "-") -> 프란츠 요제프 하이든 | G19: =_xlfn.XLOOKUP(D19, Composer!A:A, Composer!C:C, "-") -> 고전 | H19: =_xlfn.XLOOKUP(E19, Composer!B:B, Composer!D:D, "-") -> Classical | I19: 세광음악출판사 | K19: Sonaten, Tema con Variazioni, Andante con Variazioni, Fantasia, Capriccio | M19: 3 | P19: haydn1.jpg
A20: 18 | B20: Haydn Complete Piano Sonatas | C20: Haydn Sämtliche Klaviersonaten Band III | D20: Franz Joseph Haydn | E20: =_xlfn.XLOOKUP(D20, Composer!A:A, Composer!B:B, "-") -> 프란츠 요제프 하이든 | G20: =_xlfn.XLOOKUP(D20, Composer!A:A, Composer!C:C, "-") -> 고전 | H20: =_xlfn.XLOOKUP(E20, Composer!B:B, Composer!D:D, "-") -> Classical | I20: G. Henle Verlag | K20: Volume III | M20: 2 | N20: 문상혁 | Q20: https://m.media-amazon.com/images/I/5101QsDC8PL._AC_UF1000,1000_QL80_.jpg
A21: 19 | B21: Haydn Piano Variations | C21: Haydn Variationen für Klavier | D21: Franz Joseph Haydn | E21: =_xlfn.XLOOKUP(D21, Composer!A:A, Composer!B:B, "-") -> 프란츠 요제프 하이든 | G21: =_xlfn.XLOOKUP(D21, Composer!A:A, Composer!C:C, "-") -> 고전 | H21: =_xlfn.XLOOKUP(E21, Composer!B:B, Composer!D:D, "-") -> Classical | I21: G. Henle Verlag | K21: Piano Variations | M21: 2 | N21: 문상혁
A22: 20 | B22: Haydn 2 | D22: Franz Joseph Haydn | E22: =_xlfn.XLOOKUP(D22, Composer!A:A, Composer!B:B, "-") -> 프란츠 요제프 하이든 | G22: =_xlfn.XLOOKUP(D22, Composer!A:A, Composer!C:C, "-") -> 고전 | H22: =_xlfn.XLOOKUP(E22, Composer!B:B, Composer!D:D, "-") -> Classical | I22: 세광음악출판사 | K22: Sonaten 2 | M22: 3 | P22: haydn5.jpg
A23: 21 | B23: Mozart Piano Sonantas | C23: Mozart Klaviersonaten Band 2 | D23: Wolfgang Amadeus Mozart | E23: =_xlfn.XLOOKUP(D23, Composer!A:A, Composer!B:B, "-") -> 볼프강 아마데우스 모차르트 | G23: =_xlfn.XLOOKUP(D23, Composer!A:A, Composer!C:C, "-") -> 고전 | H23: =_xlfn.XLOOKUP(E23, Composer!B:B, Composer!D:D, "-") -> Classical | I23: G. Henle Verlag | K23: (스프링 제본) Volume II | M23: 3 | N23: 문상혁
A24: 22 | B24: Beethoven Variationene für Klavier | D24: Ludwig van Beethoven | E24: =_xlfn.XLOOKUP(D24, Composer!A:A, Composer!B:B, "-") -> 루트비히 판 베토벤 | G24: =_xlfn.XLOOKUP(D24, Composer!A:A, Composer!C:C, "-") -> 고전 | H24: =_xlfn.XLOOKUP(E24, Composer!B:B, Composer!D:D, "-") -> Classical | I24: G. Henle Verlag | K24: Band II | M24: 2 | N24: 문상혁
A25: 23 | B25: Beethoven Piano Concerto no. 4 in G major | C25: Klavierkonzert Nr.4 G-dur Opus 58 Klavierauszug | D25: Ludwig van Beethoven | E25: =_xlfn.XLOOKUP(D25, Composer!A:A, Composer!B:B, "-") -> 루트비히 판 베토벤 | G25: =_xlfn.XLOOKUP(D25, Composer!A:A, Composer!C:C, "-") -> 고전 | H25: =_xlfn.XLOOKUP(E25, Composer!B:B, Composer!D:D, "-") -> Classical | I25: G. Henle Verlag | K25: op.58, Piano Reduction | M25: 3 | N25: 문상혁
A26: 24 | B26: Beethoven Klavier-Werke 4 | D26: Ludwig van Beethoven | E26: =_xlfn.XLOOKUP(D26, Composer!A:A, Composer!B:B, "-") -> 루트비히 판 베토벤 | G26: =_xlfn.XLOOKUP(D26, Composer!A:A, Composer!C:C, "-") -> 고전 | H26: =_xlfn.XLOOKUP(E26, Composer!B:B, Composer!D:D, "-") -> Classical | I26: 현대음악출판사 | K26: Variationen | M26: 3
A27: 25 | B27: Beethoven Klavier-Werke 5 | D27: Ludwig van Beethoven | E27: =_xlfn.XLOOKUP(D27, Composer!A:A, Composer!B:B, "-") -> 루트비히 판 베토벤 | G27: =_xlfn.XLOOKUP(D27, Composer!A:A, Composer!C:C, "-") -> 고전 | H27: =_xlfn.XLOOKUP(E27, Composer!B:B, Composer!D:D, "-") -> Classical | I27: 태림출판사 | K27: Sieben Bagetelen Op.33 외 | M27: 3
A28: 26 | B28: 베토벤 소나타전집 1 | C28: Beethoven Klaviersonaten 1 | D28: Ludwig van Beethoven | E28: =_xlfn.XLOOKUP(D28, Composer!A:A, Composer!B:B, "-") -> 루트비히 판 베토벤 | G28: =_xlfn.XLOOKUP(D28, Composer!A:A, Composer!C:C, "-") -> 고전 | H28: =_xlfn.XLOOKUP(E28, Composer!B:B, Composer!D:D, "-") -> Classical | I28: 음악춘추사 | K28: Band 1. Sonaten Nr. 1-4 | M28: 3 | P28: beethoven2.jpg
A29: 27 | B29: 베토벤 소나타전집 2 | C29: Beethoven Klaviersonaten 2 | D29: Ludwig van Beethoven | E29: =_xlfn.XLOOKUP(D29, Composer!A:A, Composer!B:B, "-") -> 루트비히 판 베토벤 | G29: =_xlfn.XLOOKUP(D29, Composer!A:A, Composer!C:C, "-") -> 고전 | H29: =_xlfn.XLOOKUP(E29, Composer!B:B, Composer!D:D, "-") -> Classical | I29: 음악춘추사 | K29: Band 2. Sonaten Nr. 5-10 | M29: 3 | P29: beethoven3.jpg
A30: 28 | B30: 베토벤 소나타전집 3 | C30: Beethoven Klaviersonaten 3 | D30: Ludwig van Beethoven | E30: =_xlfn.XLOOKUP(D30, Composer!A:A, Composer!B:B, "-") -> 루트비히 판 베토벤 | G30: =_xlfn.XLOOKUP(D30, Composer!A:A, Composer!C:C, "-") -> 고전 | H30: =_xlfn.XLOOKUP(E30, Composer!B:B, Composer!D:D, "-") -> Classical | I30: 음악춘추사 | K30: Band 3. Sonaten Nr. 11-15 | M30: 3 | P30: beethoven4.jpg
A31: 29 | B31: 베토벤 소나타전집 4 | C31: Beethoven Klaviersonaten 4 | D31: Ludwig van Beethoven | E31: =_xlfn.XLOOKUP(D31, Composer!A:A, Composer!B:B, "-") -> 루트비히 판 베토벤 | G31: =_xlfn.XLOOKUP(D31, Composer!A:A, Composer!C:C, "-") -> 고전 | H31: =_xlfn.XLOOKUP(E31, Composer!B:B, Composer!D:D, "-") -> Classical | I31: 음악춘추사 | K31: Band 4. Sonaten Nr. 16-20 | M31: 3 | P31: beethoven5.jpg
A32: 30 | B32: 베토벤 소나타전집 5 | C32: Beethoven Klaviersonaten 5 | D32: Ludwig van Beethoven | E32: =_xlfn.XLOOKUP(D32, Composer!A:A, Composer!B:B, "-") -> 루트비히 판 베토벤 | G32: =_xlfn.XLOOKUP(D32, Composer!A:A, Composer!C:C, "-") -> 고전 | H32: =_xlfn.XLOOKUP(E32, Composer!B:B, Composer!D:D, "-") -> Classical | I32: 음악춘추사 | K32: Band 5. Sonaten Nr. 21-27 | M32: 3 | P32: beethoven6.jpg
A33: 31 | B33: 베토벤 소나타전집 6 | C33: Beethoven Klaviersonaten 6 | D33: Ludwig van Beethoven | E33: =_xlfn.XLOOKUP(D33, Composer!A:A, Composer!B:B, "-") -> 루트비히 판 베토벤 | G33: =_xlfn.XLOOKUP(D33, Composer!A:A, Composer!C:C, "-") -> 고전 | H33: =_xlfn.XLOOKUP(E33, Composer!B:B, Composer!D:D, "-") -> Classical | I33: 음악춘추사 | K33: Band 6. Sonaten Nr. 28-32 | M33: 3 | P33: beethoven7.jpg
A34: 32 | B34: 클레멘티 소나타집 2 | C34: Clementi Sonaten 2 | D34: Muzio Clementi | E34: =_xlfn.XLOOKUP(D34, Composer!A:A, Composer!B:B, "-") -> 무치오 클레멘티 | G34: =_xlfn.XLOOKUP(D34, Composer!A:A, Composer!C:C, "-") -> 고전 | H34: =_xlfn.XLOOKUP(E34, Composer!B:B, Composer!D:D, "-") -> Classical | I34: 음악춘추사 | K34: Band 4. Sonate 19-24 | M34: 1 | P34: clementi1.jpg
A35: 33 | B35: 클레멘티 소나타집 4 | C35: Clementi Sonaten 4 | D35: Muzio Clementi | E35: =_xlfn.XLOOKUP(D35, Composer!A:A, Composer!B:B, "-") -> 무치오 클레멘티 | G35: =_xlfn.XLOOKUP(D35, Composer!A:A, Composer!C:C, "-") -> 고전 | H35: =_xlfn.XLOOKUP(E35, Composer!B:B, Composer!D:D, "-") -> Classical | I35: 음악춘추사 | K35: Band 4. Sonate 8-12 | M35: 2
A36: 34 | B36: 베토벤 작품집 2 | C36: Beethoven Klavierstücke 2 | D36: Ludwig van Beethoven | E36: =_xlfn.XLOOKUP(D36, Composer!A:A, Composer!B:B, "-") -> 루트비히 판 베토벤 | G36: =_xlfn.XLOOKUP(D36, Composer!A:A, Composer!C:C, "-") -> 고전 | H36: =_xlfn.XLOOKUP(E36, Composer!B:B, Composer!D:D, "-") -> Classical | I36: 음악춘추사 | K36: Werke der Bonner Zeit, Zerke der Früheren Wiener Zeit, Werke der Späteren Wiener Jahre | M36: 3 | P36: beethoven1.jpg
A37: 35 | B37: Beethoven Sonata 1 | D37: Ludwig van Beethoven | E37: =_xlfn.XLOOKUP(D37, Composer!A:A, Composer!B:B, "-") -> 루트비히 판 베토벤 | G37: =_xlfn.XLOOKUP(D37, Composer!A:A, Composer!C:C, "-") -> 고전 | H37: =_xlfn.XLOOKUP(E37, Composer!B:B, Composer!D:D, "-") -> Classical | I37: 정보 없음 | K37: (스프링 제본) | M37: 3
A38: 36 | B38: Schubert Klavier-Werke 1 | D38: Franz Peter Schubert | E38: =_xlfn.XLOOKUP(D38, Composer!A:A, Composer!B:B, "-") -> 프란츠 페터 슈베르트 | G38: =_xlfn.XLOOKUP(D38, Composer!A:A, Composer!C:C, "-") -> 낭만 | H38: =_xlfn.XLOOKUP(E38, Composer!B:B, Composer!D:D, "-") -> Romantic | I38: 현대음악출판사 | K38: Sonaten 1 | L38: 1. Op.42 a-moll / 2. Op.53 D-dur / 3. Op.120 A-dur / 4. Op.122 Es-dur / 5. Op.143 a-moll, 6. Op.147 H-dur | M38: 3 | P38: schubert5.jpg
A39: 37 | B39: 슈베르트 소나타집 1 | C39: Schubert Klaviersonaten 1 | D39: Franz Peter Schubert | E39: =_xlfn.XLOOKUP(D39, Composer!A:A, Composer!B:B, "-") -> 프란츠 페터 슈베르트 | G39: =_xlfn.XLOOKUP(D39, Composer!A:A, Composer!C:C, "-") -> 낭만 | H39: =_xlfn.XLOOKUP(E39, Composer!B:B, Composer!D:D, "-") -> Romantic | I39: 음악춘추사 | K39: Band 1. Sonaten Nr. 1-4 | L39: D.537 / D.568 / D.575 / D.664 | M39: 3 | P39: schubert1.jpg
A40: 38 | B40: 슈베르트 소나타집 2 | C40: Schubert Klaviersonaten 2 | D40: Franz Peter Schubert | E40: =_xlfn.XLOOKUP(D40, Composer!A:A, Composer!B:B, "-") -> 프란츠 페터 슈베르트 | G40: =_xlfn.XLOOKUP(D40, Composer!A:A, Composer!C:C, "-") -> 낭만 | H40: =_xlfn.XLOOKUP(E40, Composer!B:B, Composer!D:D, "-") -> Romantic | I40: 음악춘추사 | K40: Band 2. Sonaten Nr. 4-7 | L40: D.664 / D.784 / D.845 / D.850 | M40: 3 | P40: schubert2.jpg
...

Sheet Composer
A1: composer_org | B1: composer_kor | C1: era | D1: era_eng
A2: - | B2: 정보 없음 | C2: 분류 없음 | D2: =_xlfn.XLOOKUP(C2, Era!A:A, Era!B:B, "-") -> No category
A3: Various | B3: 여러 작곡가 | C3: 분류 없음 | D3: =_xlfn.XLOOKUP(C3, Era!A:A, Era!B:B, "-") -> No category
A4: Various (Romantic) | B4: 여러 작곡가 (낭만) | C4: 낭만 | D4: =_xlfn.XLOOKUP(C4, Era!A:A, Era!B:B, "-") -> Romantic
A5: Various (Comtemporary) | B5: 여러 작곡가 (현대) | C5: 현대 | D5: =_xlfn.XLOOKUP(C5, Era!A:A, Era!B:B, "-") -> Contemporary
A6: Various (Pop/New age) | B6: 여러 작곡가 (팝/뉴에이지) | C6: 팝/뉴에이지 | D6: =_xlfn.XLOOKUP(C6, Era!A:A, Era!B:B, "-") -> Pop/New Age
A7: Various (Jazz) | B7: 여러 작곡가 (재즈) | C7: 재즈 | D7: =_xlfn.XLOOKUP(C7, Era!A:A, Era!B:B, "-") -> Jazz
A8: George Frideric Handel | B8: 게오르크 프리드리히 헨델 | C8: 바로크 | D8: =_xlfn.XLOOKUP(C8, Era!A:A, Era!B:B, "-") -> Baroque
A9: Domenico Scarlatti | B9: 도메니코 스카를라티 | C9: 바로크 | D9: =_xlfn.XLOOKUP(C9, Era!A:A, Era!B:B, "-") -> Baroque
A10: Johann Sebastian Bach | B10: 요한 세바스티안 바흐 | C10: 바로크 | D10: =_xlfn.XLOOKUP(C10, Era!A:A, Era!B:B, "-") -> Baroque
A11: Wolfgang Amadeus Mozart | B11: 볼프강 아마데우스 모차르트 | C11: 고전 | D11: =_xlfn.XLOOKUP(C11, Era!A:A, Era!B:B, "-") -> Classical
A12: Franz Joseph Haydn | B12: 프란츠 요제프 하이든 | C12: 고전 | D12: =_xlfn.XLOOKUP(C12, Era!A:A, Era!B:B, "-") -> Classical
A13: Ludwig van Beethoven | B13: 루트비히 판 베토벤 | C13: 고전 | D13: =_xlfn.XLOOKUP(C13, Era!A:A, Era!B:B, "-") -> Classical
... A61: George Winston | B61: 조지 윈스턴 | C61: 팝/뉴에이지 | D61: =_xlfn.XLOOKUP(C61, Era!A:A, Era!B:B, "-") -> Pop/New Age
C62: 분류 없음 | D62: =_xlfn.XLOOKUP(C62, Era!A:A, Era!B:B, "-") -> No category
C63: 분류 없음 | D63: =_xlfn.XLOOKUP(C63, Era!A:A, Era!B:B, "-") -> No category
C64: 분류 없음 | D64: =_xlfn.XLOOKUP(C64, Era!A:A, Era!B:B, "-") -> No category
C65: 분류 없음 | D65: =_xlfn.XLOOKUP(C65, Era!A:A, Era!B:B, "-") -> No category
C66: 분류 없음 | D66: =_xlfn.XLOOKUP(C66, Era!A:A, Era!B:B, "-") -> No category
C67: 분류 없음 | D67: =_xlfn.XLOOKUP(C67, Era!A:A, Era!B:B, "-") -> No category
C68: 분류 없음 | D68: =_xlfn.XLOOKUP(C68, Era!A:A, Era!B:B, "-") -> No category
C69: 분류 없음 | D69: =_xlfn.XLOOKUP(C69, Era!A:A, Era!B:B, "-") -> No category
C70: 분류 없음 | D70: =_xlfn.XLOOKUP(C70, Era!A:A, Era!B:B, "-") -> No category
C71: 분류 없음 | D71: =_xlfn.XLOOKUP(C71, Era!A:A, Era!B:B, "-") -> No category
C72: 분류 없음 | D72: =_xlfn.XLOOKUP(C72, Era!A:A, Era!B:B, "-") -> No category
C73: 분류 없음 | D73: =_xlfn.XLOOKUP(C73, Era!A:A, Era!B:B, "-") -> No category
... C100: 분류 없음 | D100: =_xlfn.XLOOKUP(C100, Era!A:A, Era!B:B, "-") -> No category

Sheet Era
A1: 분류 | B1: 분류(영문)
A2: 바로크 | B2: Baroque
A3: 고전 | B3: Classical
A4: 낭만 | B4: Romantic
A5: 인상주의 | B5: Impressionism
A6: 근대 | B6: Modern
A7: 현대 | B7: Contemporary
A8: 팝/뉴에이지 | B8: Pop/New Age
A9: 재즈 | B9: Jazz
A10: 분류 없음 | B10: No category
